<!--
 ~ Copyright 2019 The ROBEL Authors.
 ~
 ~ Licensed under the Apache License, Version 2.0 (the "License");
 ~ you may not use this file except in compliance with the License.
 ~ You may obtain a copy of the License at
 ~
 ~     http://www.apache.org/licenses/LICENSE-2.0
 ~
 ~ Unless required by applicable law or agreed to in writing, software
 ~ distributed under the License is distributed on an "AS IS" BASIS,
 ~ WITHOUT WARRANTIES OR CONDITIONS OF ANY KIND, either express or implied.
 ~ See the License for the specific language governing permissions and
 ~ limitations under the License.
 -->

<?xml version="1.0"?>
<mujocoinclude>
        <body name="palm" pos="0 0 0.01" childclass="dHand">
          <geom euler="1.57 0 1.57" mesh="motor" pos="0.012 0 0.112"/>
          <geom euler="1.57 0 1.66" mesh="motor" pos="-0.042 0 0.111"/>
          <geom euler="1.57 0 1.484" mesh="motor" pos="0.066 0 0.111"/>
          <geom material="visual_white" euler="1.57 0 1.57" mesh="PalmInterior" pos="0.011 0 0.053"/>
          <geom euler="-1.57 0 1.57" mesh="topPlate" pos="0.0275 0.028 0.054" material="visual_chrome"/>
          <geom euler="1.57 0 1.57" mesh="Palmplate" pos="0.013 -0.025 0.061"/>
          <geom class="phys_metal" pos="-0.011 0 0.048" size="0.047 0.027 0.037" type="box" mass=".300"/>
          <geom class="phys_metal" pos="-0.044 0 -.002" size="0.014 0.027 0.013" type="box" mass=".150"/>
          <geom class="phys_metal" pos="0.012 0 0.109" size="0.015 0.017 0.024" type="box" mass=".086"/>
          <geom class="phys_metal" euler="0 0.087 0" pos="0.066 0 0.108" size="0.015 0.018 0.024" type="box" mass=".086"/>
          <geom class="phys_metal" euler="0 -0.087 0" pos="-0.042 0 0.108" size="0.015 0.018 0.024" type="box" mass=".086"/>
          <geom class="phys_metal" pos="0.06 0 0.068" size="0.026 0.027 0.016" type="box" mass=".150"/>
          <geom class="phys_metal" pos="0 -0.0248 -.002" size="0.03 0.002 0.013" type="box" mass=".30"/>
          <geom class="phys_metal" pos="0 0.0248 -.002" size="0.03 0.002 0.013" type="box" mass=".30"/>
          <geom class="phys_metal" pos="0.014 -0.025 0.109" size="0.072 0.002 0.026" type="box" mass=".50"/>
          <geom class="phys_metal" pos="0.014 0.025 0.109" size="0.072 0.002 0.026" type="box" mass=".50"/>
          <geom class="phys_metal" pos="0.047 0 -.001" size="0.017 0.027 0.0145" type="box" mass=".79"/>
          <site name="grasp" pos="0 -.125 .1" type="sphere" size="0.020"/>
          <!-- INDEX/FIRST FINGER -->
          <body euler="0 0.087 0" name="FF_metacarpel" pos="0.067 0 0.12">
            <joint axis="0 1 0" name="FF_ADB" class="ADB"/>
            <geom euler="-1.57 3.14 -1.57" mesh="knuckle"/>
            <geom euler="1.57 -1.57 0" mesh="motor" pos="0 0 0.037"/>
            <geom class="phys_metal" pos="0 0 0.021" size="0.015 0.021 0.002" type="box" mass=".003"/>
            <geom class="phys_metal" pos="0 0.02 0.01" size="0.015 0.001 0.014" type="box" mass=".001"/>
            <geom class="phys_metal" pos="0 -0.02 0.01" size="0.015 0.001 0.014" type="box" mass=".001"/>
            <geom class="phys_metal" pos="0 0.003 0.037" size="0.018 0.024 0.015" type="box" mass=".086"/>
            <body name="FF_proximal" pos="0 -0.009 0.037">
              <joint axis="1 0 0" name="FF_MCP" class="MCP"/>
              <geom euler="0 -1.57 0" mesh="bracket2" pos="-0.018 0 0.012"/>
              <geom euler="0 1.57 3.14" mesh="bracket2" pos="0.018 0 0.012"/>
              <geom euler="0 -1.57 0" mesh="motor" pos="0 0 0.0445"/>
              <geom class="phys_metal" pos="0.02 0 0.012" size="0.0015 0.015 0.014" type="box" mass=".003"/>
              <geom class="phys_metal" pos="-0.02 0 0.012" size="0.0015 0.015 0.014" type="box" mass=".003"/>
              <geom class="phys_metal" pos="0 0 0.041" size="0.018 0.015 0.024" type="box" mass=".086"/>
              <body name="FF_middle" pos="0 0 0.054">
                <joint axis="1 0 0" name="FF_PIP" class="PIP"/>
                <geom euler="0 1.57 3.14" mesh="bracket2" pos="0.018 0 0.011"/>
                <geom euler="0 -1.57 0" mesh="bracket2" pos="-0.018 0 0.011"/>
                <geom euler="0 -1.57 0" mesh="motor" pos="0 0 0.0436"/>
                <geom class="phys_metal" pos="0.02 0 0.011" size="0.0015 0.015 0.014" type="box" mass=".003"/>
                <geom class="phys_metal" pos="-0.02 0 0.011" size="0.0015 0.015 0.014" type="box" mass=".003"/>
                <geom class="phys_metal" pos="0 0 0.041" size="0.018 0.015 0.024" type="box" mass=".086"/>
                <body name="FF_distal" pos="0 0 0.052">
                  <joint axis="1 0 0" name="FF_DIP" class="DIP"/>
                  <geom euler="0 -1.57 0" mesh="bracket2" pos="-0.018 0 0.012"/>
                  <geom euler="0 1.57 3.14" mesh="bracket2" pos="0.018 0 0.012"/>
                  <geom material="visual_blue" euler="1.57 0 1.57" mesh="finger" pos="0 0 0.04"/>
                  <geom class="phys_metal" pos="-0.02 0 0.012" size="0.0015 0.015 0.014" type="box" mass=".003"/>
                  <geom class="phys_metal" pos="0.02 0 0.012" size="0.0015 0.015 0.014" type="box" mass=".003"/>
                  <geom class="phys_metal" pos="0 0 0.045" size="0.019" type="sphere" mass=".01"/>
                  <geom class="phys_metal" pos="0 0 0.033" size="0.019 .01" type="cylinder" mass=".007"/>
                  <geom class="phys_metal" pos="0 0 0.022" size="0.019 .018 .005" type="box" mass=".004"/>
                  <site name="FFtip" type="sphere" pos="0 0 0.045" size="0.01" rgba="1 .3 .3 1"/>
                </body>
              </body>
            </body>
          </body>
          <!-- MIDDLE FINGER -->
          <body name="MF_metacarpel" pos="0.012 0 0.121">
            <joint axis="0 1 0" name="MF_ADB" class="ADB"/>
            <geom euler="-1.57 3.14 -1.57" mesh="knuckle"/>
            <geom euler="1.57 -1.57 0" mesh="motor" pos="0 0 0.037"/>
            <geom class="phys_metal" pos="0 0 0.021" size="0.015 0.021 0.002" type="box" mass=".003"/>
            <geom class="phys_metal" pos="0 0.02 0.01" size="0.015 0.001 0.014" type="box" mass=".001"/>
            <geom class="phys_metal" pos="0 -0.02 0.01" size="0.015 0.001 0.014" type="box" mass=".001"/>
            <geom class="phys_metal" pos="0 0.003 0.037" size="0.018 0.024 0.015" type="box" mass=".086"/>
            <body name="MF_proximal" pos="0 -0.009 0.037">
              <joint axis="1 0 0" name="MF_MCP" class="MCP"/>
              <geom euler="0 -1.57 0" mesh="bracket2" pos="-0.018 0 0.012"/>
              <geom euler="0 1.57 3.14" mesh="bracket2" pos="0.018 0 0.012"/>
              <geom euler="0 -1.57 0" mesh="motor" pos="0 0 0.0445"/>
              <geom class="phys_metal" pos="0.02 0 0.012" size="0.0015 0.015 0.014" type="box" mass=".003"/>
              <geom class="phys_metal" pos="-0.02 0 0.012" size="0.0015 0.015 0.014" type="box" mass=".003"/>
              <geom class="phys_metal" pos="0 0 0.041" size="0.018 0.015 0.024" type="box" mass=".086"/>
              <body name="MF_middle" pos="0 0 0.054">
                <joint axis="1 0 0" name="MF_PIP" class="PIP"/>
                <geom euler="0 1.57 3.14" mesh="bracket2" pos="0.018 0 0.011"/>
                <geom euler="0 -1.57 0" mesh="bracket2" pos="-0.018 0 0.011"/>
                <geom euler="0 -1.57 0" mesh="motor" pos="0 0 0.0436"/>
                <geom class="phys_metal" pos="0.02 0 0.011" size="0.0015 0.015 0.014" type="box" mass=".003"/>
                <geom class="phys_metal" pos="-0.02 0 0.011" size="0.0015 0.015 0.014" type="box" mass=".003"/>
                <geom class="phys_metal" pos="0 0 0.041" size="0.018 0.015 0.024" type="box" mass=".086"/>
                <body name="MF_distal" pos="0 0 0.052">
                  <joint axis="1 0 0" name="MF_DIP" class="DIP"/>
                  <geom euler="0 -1.57 0" mesh="bracket2" pos="-0.018 0 0.012"/>
                  <geom euler="0 1.57 3.14" mesh="bracket2" pos="0.018 0 0.012"/>
                  <geom material="visual_blue" euler="1.57 0 1.57" mesh="finger" pos="0 0 0.04"/>
                  <geom class="phys_metal" pos="-0.02 0 0.012" size="0.0015 0.015 0.014" type="box" mass=".003"/>
                  <geom class="phys_metal" pos="0.02 0 0.012" size="0.0015 0.015 0.014" type="box" mass=".003"/>
                  <geom class="phys_metal" pos="0 0 0.045" size="0.019" type="sphere" mass=".01"/>
                  <geom class="phys_metal" pos="0 0 0.033" size="0.019 .01" type="cylinder" mass=".007"/>
                  <geom class="phys_metal" pos="0 0 0.022" size="0.019 .018 .005" type="box" mass=".004"/>
                  <site name="MFtip" type="sphere" pos="0 0 0.045" size="0.01" rgba=".3 1 .3 1"/>
                </body>
              </body>
            </body>
          </body>
          <!-- PINKY FINGER -->
          <body euler="0 -0.087 0" name="PF_metacarpel" pos="-0.043 0 0.12">
            <joint axis="0 1 0" name="PF_ADB" class="ADB"/>
            <geom euler="-1.57 3.14 -1.57" mesh="knuckle"/>
            <geom euler="1.57 -1.57 0" mesh="motor" pos="0 0 0.037"/>
            <geom class="phys_metal" pos="0 0 0.021" size="0.015 0.021 0.002" type="box" mass=".003"/>
            <geom class="phys_metal" pos="0 0.02 0.01" size="0.015 0.001 0.014" type="box" mass=".001"/>
            <geom class="phys_metal" pos="0 -0.02 0.01" size="0.015 0.001 0.014" type="box" mass=".001"/>
            <geom class="phys_metal" pos="0 0.003 0.037" size="0.018 0.024 0.015" type="box" mass=".086"/>
            <body name="PF_proximal" pos="0 -0.009 0.037">
              <joint axis="1 0 0" name="PF_MCP" class="MCP"/>
              <geom euler="0 -1.57 0" mesh="bracket2" pos="-0.018 0 0.012"/>
              <geom euler="0 1.57 3.14" mesh="bracket2" pos="0.018 0 0.012"/>
              <geom euler="0 -1.57 0" mesh="motor" pos="0 0 0.0445"/>
              <geom class="phys_metal" pos="0.02 0 0.012" size="0.0015 0.015 0.014" type="box" mass=".003"/>
              <geom class="phys_metal" pos="-0.02 0 0.012" size="0.0015 0.015 0.014" type="box" mass=".003"/>
              <geom class="phys_metal" pos="0 0 0.041" size="0.018 0.015 0.024" type="box" mass=".086"/>
              <body name="PF_middle" pos="0 0 0.054">
                <joint axis="1 0 0" name="PF_PIP" class="PIP"/>
                <geom euler="0 1.57 3.14" mesh="bracket2" pos="0.018 0 0.011"/>
                <geom euler="0 -1.57 0" mesh="bracket2" pos="-0.018 0 0.011"/>
                <geom euler="0 -1.57 0" mesh="motor" pos="0 0 0.0436"/>
                <geom class="phys_metal" pos="0.02 0 0.012" size="0.0015 0.015 0.014" type="box" mass=".003"/>
                <geom class="phys_metal" pos="-0.02 0 0.012" size="0.0015 0.015 0.014" type="box" mass=".003"/>
                <geom class="phys_metal" pos="0 0 0.041" size="0.018 0.015 0.024" type="box" mass=".086"/>
                <body name="PF_distal" pos="0 0 0.052">
                  <joint axis="1 0 0" name="PF_DIP" class="DIP"/>
                  <geom euler="0 -1.57 0" mesh="bracket2" pos="-0.018 0 0.012"/>
                  <geom euler="0 1.57 3.14" mesh="bracket2" pos="0.018 0 0.012"/>
                  <geom material="visual_blue" euler="1.57 0 1.57" mesh="finger" pos="0 0 0.04"/>
                  <geom class="phys_metal" pos="-0.02 0 0.011" size="0.0015 0.015 0.014" type="box" mass=".003"/>
                  <geom class="phys_metal" pos="0.02 0 0.011" size="0.0015 0.015 0.014" type="box" mass=".003"/>
                  <geom class="phys_metal" pos="0 0 0.045" size="0.019" type="sphere" mass=".01"/>
                  <geom class="phys_metal" pos="0 0 0.033" size="0.019 .01" type="cylinder" mass=".007"/>
                  <geom class="phys_metal" pos="0 0 0.022" size="0.019 .018 .005" type="box" mass=".004"/>
                  <site name="PFtip" type="sphere" pos="0 0 0.045" size="0.01" rgba=".3 .3 1 1"/>
                </body>
              </body>
            </body>
          </body>
          <!-- THUMB -->
          <body euler="0 1.658 0" name="TF" pos="0.055 0 0.04">
            <joint axis="1 0 0" name="TF_MCP" class="MCP"/>
            <geom euler="0 0 3.14" mesh="motor" pos="0.009 0 0.052"/>
            <geom euler="-3.14 -1.57 0" mesh="motor" pos="0.006 0 0.009"/>
            <geom material="visual_chrome" euler="1.57 0 1.57" mesh="thumb_bracket" pos="0.015 0.016 0.031"/>
            <geom material="visual_chrome" euler="1.57 0 1.57" mesh="thumb_bracket" pos="0.015 -0.016 0.031"/>
            <geom class="phys_metal" pos="0.006 0 0.012" size="0.018 0.018 0.024" type="box" mass=".092"/>
            <geom class="phys_metal" pos="0.012 0 0.052" size="0.024 0.018 0.017" type="box" mass=".092"/>
            <body name="TF_metacarpel" pos="0 0 0.072">
              <joint axis="0 0 1" name="TF_ADB" range="-2.57 .57"/>
              <geom euler="1.57 0 1.57" mesh="bracket1" pos="0 0 0.0015"/>
              <geom euler="0 -1.57 0" mesh="motor" pos="0 0 0.031"/>
              <geom class="phys_metal" pos="0 0 0.028" size="0.018 0.015 0.024" type="box"/>
              <geom class="phys_metal" pos="0 0 0.005" size="0.019 0.014 0.006" type="box"/>
              <body name="TF_middle" pos="0 0 0.0405">
                <joint axis="1 0 0" name="TF_PIP" class="PIP"/>
                <geom euler="0 -1.57 0" mesh="bracket2" pos="-0.018 0 0.011"/>
                <geom euler="3.14 1.57 0" mesh="bracket2" pos="0.017 0 0.011"/>
                <geom euler="0 -1.57 0" mesh="motor" pos="0 0 0.044"/>
                <geom class="phys_metal" pos="-0.02 0 0.011" size="0.0015 0.015 0.014" type="box" mass=".003"/>
                <geom class="phys_metal" pos="0.02 0 0.011" size="0.0015 0.015 0.014" type="box" mass=".003"/>
                <geom class="phys_metal" pos="0 0 0.041" size="0.018 0.015 0.024" type="box" mass=".086"/>
                <body name="TF_distal" pos="0 0 0.0535">
                  <joint axis="1 0 0" name="TF_DIP" class="DIP"/>
                  <geom euler="3.14 1.57 0" mesh="bracket2" pos="0.017 0 0.011"/>
                  <geom euler="0 -1.57 0" mesh="bracket2" pos="-0.018 0 0.011"/>
                  <geom material="visual_blue" euler="1.57 0 1.57" mesh="finger" pos="0 0 0.04"/>
                  <geom class="phys_metal" pos="-0.02 0 0.011" size="0.0015 0.015 0.014" type="box" mass=".003"/>
                  <geom class="phys_metal" pos="0.02 0 0.011" size="0.0015 0.015 0.014" type="box" mass=".003"/>
                  <geom class="phys_metal" pos="0 0 0.045" size="0.019" type="sphere" mass=".01"/>
                  <geom class="phys_metal" pos="0 0 0.033" size="0.019 .01" type="cylinder" mass=".007"/>
                  <geom class="phys_metal" pos="0 0 0.022" size="0.019 .018 .005" type="box" mass=".004"/>
                  <site name="TFtip" type="sphere" pos="0 0 0.045" size="0.01" rgba="1 1 .3 1"/>
                </body>
              </body>
            </body>
          </body>
        </body>
</mujocoinclude>
