<!--
 ~ Copyright 2019 The ROBEL Authors.
 ~
 ~ Licensed under the Apache License, Version 2.0 (the "License");
 ~ you may not use this file except in compliance with the License.
 ~ You may obtain a copy of the License at
 ~
 ~     http://www.apache.org/licenses/LICENSE-2.0
 ~
 ~ Unless required by applicable law or agreed to in writing, software
 ~ distributed under the License is distributed on an "AS IS" BASIS,
 ~ WITHOUT WARRANTIES OR CONDITIONS OF ANY KIND, either express or implied.
 ~ See the License for the specific language governing permissions and
 ~ limitations under the License.
 -->

<?xml version="1.0"?>
<mujocoinclude>
  <body name="dClaw" euler="3.14 0 0" childclass="dclaw3xh">
    <geom material="acrylic" mesh="acrylic_circle"/>
    <geom class="phy_metal" type="cylinder" size="0.075 0.004" mass=".11"/>
    <site name="S_grasp" pos="0 0 0.24" type="sphere" size="0.01" group="4"/>
    <!-- INDEX/FIRST FINGER -->
    <body name="FFbase" pos=".03 -0.052 .003" euler="0 0 .52">
      <geom mesh="xh28" pos="0 0 0.01425" euler="1.57 0 1.57"/>
      <geom class="phy_metal" type="box" pos=".012 0 0.014" size="0.024 0.0175 0.015" mass=".093"/>
      <body name="FF10" pos="0 0 0.01425" euler="0 0 3.14">
        <geom mesh="metal_clamping" euler="0 0 1.57"/>
        <geom mesh="metal_clamping_small" pos="0 0 0.055" euler="3.14 0 0"/>
        <geom mesh="xh28" pos="0 0 0.068" euler="1.57 1.57 0"/>
        <geom class="phy_metal" type="box" pos="0 0 0.056" size="0.0175 0.015 0.024" mass=".093"/>
        <geom class="phy_metal" type="box" pos="0.0 0 0.026" size="0.0125 0.0214 0.003" mass=".003"/>
        <geom class="phy_metal" type="box" pos="0 0.02 0.013" size="0.011 0.0012 0.016" mass=".002"/>
        <geom class="phy_metal" type="box" pos="0 -0.02 0.013" size="0.011 0.0012 0.016" mass=".002"/>
        <geom class="phy_metal" type="box" pos="0 0 0.033" size="0.019 0.014 0.006" mass=".005"/>
        <joint name="FFJ10" type="hinge" axis="0 1 0" range="-.45 1.35"/>
        <body name="FFL11" pos="0 0 0.0675">
          <geom mesh="metal_clamping_small" pos="0 0 0.055" euler="3.14 0 0"/>
          <geom mesh="xh28" pos="0 0 0.0686" euler="1.57 1.57 0"/>
          <geom mesh="metal_clamping"/>
          <geom class="phy_metal" type="box" pos="0 0 0.056" size="0.0175 0.015 0.024" mass=".093"/>
          <geom class="phy_metal" type="box" pos="0 0 0.026" size="0.0214 0.0125 0.003" mass=".003"/>
          <geom class="phy_metal" type="box" pos="0.02 0 0.013" size="0.0012 0.011 0.016" mass=".002"/>
          <geom class="phy_metal" type="box" pos="-0.02 0 0.013" size="0.0012 0.011 0.016" mass=".002"/>
          <geom class="phy_metal" type="box" pos="0 0 0.033" size="0.019 0.014 0.006" mass=".005"/>
          <joint name="FFJ11" type="hinge" axis="1 0 0" range="-2 2"/>
          <body name="FFL12" pos="0 0 0.068">
            <geom mesh="metal_clamping"/>
            <geom material="plastic" mesh="plastic_finger" pos="0 0 0.046"/>
            <geom class="phy_metal" type="box" pos="0.0 0 0.026" size="0.0214 0.0125 0.003" mass=".003"/>
            <geom class="phy_metal" type="box" pos="0.02 0 0.013" size="0.0012 0.011 0.016" mass=".002"/>
            <geom class="phy_metal" type="box" pos="-0.02 0 0.013" size="0.0012 0.011 0.016" mass=".002"/>
            <geom class="phy_plastic" type="capsule" pos="0 0 0.053" size="0.011 0.02" mass=".018"/>
            <geom class="phy_plastic" type="box" pos="0 0 0.03" size="0.0245 0.014 0.003" mass=".007"/>
            <joint name="FFJ12" type="hinge" axis="1 0 0" range="-2 2"/>
            <site name="FFtip" type="sphere" pos="0 0 .076" size="0.01" rgba="1 .3 .3 1"/>
          </body>
        </body>
      </body>
    </body>
    <!-- MIDDLE FINGER -->
    <body name="MFbase" pos=".03 0.052 .003" euler="0 0 2.6">
      <geom mesh="xh28" pos="0 0 0.01425" euler="1.57 0 1.57"/>
      <geom class="phy_metal" type="box" pos=".012 0 0.014" size="0.024 0.0175 0.015" mass=".093"/>
      <body name="MF20" pos="0 0 0.01425" euler="0 0 3.14">
        <geom mesh="metal_clamping" euler="0 0 1.57"/>
        <geom mesh="metal_clamping_small" pos="0 0 0.055" euler="3.14 0 0"/>
        <geom mesh="xh28" pos="0 0 0.068" euler="1.57 1.57 0"/>
        <geom class="phy_metal" type="box" pos="0 0 0.056" size="0.0175 0.015 0.024" mass=".093"/>
        <geom class="phy_metal" type="box" pos="0.0 0 0.026" size="0.0125 0.0214 0.003" mass=".003"/>
        <geom class="phy_metal" type="box" pos="0 0.02 0.013" size="0.011 0.0012 0.016" mass=".002"/>
        <geom class="phy_metal" type="box" pos="0 -0.02 0.013" size="0.011 0.0012 0.016" mass=".002"/>
        <geom class="phy_metal" type="box" pos="0 0 0.033" size="0.019 0.014 0.006" mass=".005"/>
        <joint name="MFJ20" type="hinge" axis="0 1 0" range="-.45 1.35"/>
        <body name="MFL21" pos="0 0 0.0675">
          <geom mesh="metal_clamping_small" pos="0 0 0.055" euler="3.14 0 0"/>
          <geom mesh="xh28" pos="0 0 0.0686" euler="1.57 1.57 0"/>
          <geom mesh="metal_clamping"/>
          <geom class="phy_metal" type="box" pos="0 0 0.056" size="0.0175 0.015 0.024" mass=".093"/>
          <geom class="phy_metal" type="box" pos="0 0 0.026" size="0.0214 0.0125 0.003" mass=".003"/>
          <geom class="phy_metal" type="box" pos="0.02 0 0.013" size="0.0012 0.011 0.016" mass=".002"/>
          <geom class="phy_metal" type="box" pos="-0.02 0 0.013" size="0.0012 0.011 0.016" mass=".002"/>
          <geom class="phy_metal" type="box" pos="0 0 0.033" size="0.019 0.014 0.006" mass=".005"/>
          <joint name="MFJ21" type="hinge" axis="1 0 0" range="-2 2"/>
          <body name="MFL22" pos="0 0 0.068">
            <geom mesh="metal_clamping"/>
            <geom material="plastic" mesh="plastic_finger" pos="0 0 0.046"/>
            <geom class="phy_metal" type="box" pos="0.0 0 0.026" size="0.0214 0.0125 0.003" mass=".003"/>
            <geom class="phy_metal" type="box" pos="0.02 0 0.013" size="0.0012 0.011 0.016" mass=".002"/>
            <geom class="phy_metal" type="box" pos="-0.02 0 0.013" size="0.0012 0.011 0.016" mass=".002"/>
            <geom class="phy_plastic" type="capsule" pos="0 0 0.053" size="0.011 0.02" mass=".018"/>
            <geom class="phy_plastic" type="box" pos="0 0 0.03" size="0.0245 0.014 0.003" mass=".007"/>
            <joint name="MFJ22" type="hinge" axis="1 0 0" range="-2 2"/>
            <site name="MFtip" type="sphere" pos="0 0 .076" size="0.01" rgba=".3 1 .3 1"/>
          </body>
        </body>
      </body>
    </body>
    <!-- THUMB -->
    <body name="THbase" pos="-.06 0 .003" euler="0 0 -1.57">
      <geom mesh="xh28" pos="0 0 0.01425" euler="1.57 0 1.57"/>
      <geom class="phy_metal" type="box" pos=".012 0 0.014" size="0.024 0.0175 0.015" mass=".093"/>
      <body name="TH30" pos="0 0 0.01425" euler="0 0 3.14">
        <geom mesh="metal_clamping" euler="0 0 1.57"/>
        <geom mesh="metal_clamping_small" pos="0 0 0.055" euler="3.14 0 0"/>
        <geom mesh="xh28" pos="0 0 0.068" euler="1.57 1.57 0"/>
        <geom class="phy_metal" type="box" pos="0 0 0.056" size="0.0175 0.015 0.024" mass=".093"/>
        <geom class="phy_metal" type="box" pos="0.0 0 0.026" size="0.0125 0.0214 0.003" mass=".003"/>
        <geom class="phy_metal" type="box" pos="0 0.02 0.013" size="0.011 0.0012 0.016" mass=".002"/>
        <geom class="phy_metal" type="box" pos="0 -0.02 0.013" size="0.011 0.0012 0.016" mass=".002"/>
        <geom class="phy_metal" type="box" pos="0 0 0.033" size="0.019 0.014 0.006" mass=".005"/>
        <joint name="THJ30" type="hinge" axis="0 1 0" range="-.45 1.35"/>
        <body name="THL31" pos="0 0 0.0675">
          <geom mesh="metal_clamping_small" pos="0 0 0.055" euler="3.14 0 0"/>
          <geom mesh="xh28" pos="0 0 0.0686" euler="1.57 1.57 0"/>
          <geom mesh="metal_clamping"/>
          <geom class="phy_metal" type="box" pos="0 0 0.056" size="0.0175 0.015 0.024" mass=".093"/>
          <geom class="phy_metal" type="box" pos="0 0 0.026" size="0.0214 0.0125 0.003" mass=".003"/>
          <geom class="phy_metal" type="box" pos="0.02 0 0.013" size="0.0012 0.011 0.016" mass=".002"/>
          <geom class="phy_metal" type="box" pos="-0.02 0 0.013" size="0.0012 0.011 0.016" mass=".002"/>
          <geom class="phy_metal" type="box" pos="0 0 0.033" size="0.019 0.014 0.006" mass=".005"/>
          <joint name="THJ31" type="hinge" axis="1 0 0" range="-2 2"/>
          <body name="THL32" pos="0 0 0.068">
            <geom mesh="metal_clamping"/>
            <geom material="plastic" mesh="plastic_finger" pos="0 0 0.046"/>
            <geom class="phy_metal" type="box" pos="0.0 0 0.026" size="0.0214 0.0125 0.003" mass=".003"/>
            <geom class="phy_metal" type="box" pos="0.02 0 0.013" size="0.0012 0.011 0.016" mass=".002"/>
            <geom class="phy_metal" type="box" pos="-0.02 0 0.013" size="0.0012 0.011 0.016" mass=".002"/>
            <geom class="phy_plastic" type="capsule" pos="0 0 0.053" size="0.011 0.02" mass=".018"/>
            <geom class="phy_plastic" type="box" pos="0 0 0.03" size="0.0245 0.014 0.003" mass=".007"/>
            <joint name="THJ32" type="hinge" axis="1 0 0" range="-2 2"/>
            <site name="THtip" type="sphere" pos="0 0 .076" size="0.01" rgba=".3 .3 1 1"/>
          </body>
        </body>
      </body>
    </body>
  </body>
</mujocoinclude>
